2022-03-30 16:43:27,021 INFO: Microblog startup [in /home/desenvolvimento/Documentos/projetos/flask/microblog/app/__init__.py:46]
2022-03-30 16:43:41,015 ERROR: Exception on /edit_profile [POST] [in /home/desenvolvimento/Documentos/projetos/flask/microblog/venv/lib/python3.9/site-packages/flask/app.py:1455]
Traceback (most recent call last):
  File "/home/desenvolvimento/Documentos/projetos/flask/microblog/venv/lib/python3.9/site-packages/sqlalchemy/engine/base.py", line 1808, in _execute_context
    self.dialect.do_execute(
  File "/home/desenvolvimento/Documentos/projetos/flask/microblog/venv/lib/python3.9/site-packages/sqlalchemy/engine/default.py", line 732, in do_execute
    cursor.execute(statement, parameters)
sqlite3.IntegrityError: UNIQUE constraint failed: user.username

The above exception was the direct cause of the following exception:

Traceback (most recent call last):
  File "/home/desenvolvimento/Documentos/projetos/flask/microblog/venv/lib/python3.9/site-packages/flask/app.py", line 2077, in wsgi_app
    response = self.full_dispatch_request()
  File "/home/desenvolvimento/Documentos/projetos/flask/microblog/venv/lib/python3.9/site-packages/flask/app.py", line 1525, in full_dispatch_request
    rv = self.handle_user_exception(e)
  File "/home/desenvolvimento/Documentos/projetos/flask/microblog/venv/lib/python3.9/site-packages/flask/app.py", line 1523, in full_dispatch_request
    rv = self.dispatch_request()
  File "/home/desenvolvimento/Documentos/projetos/flask/microblog/venv/lib/python3.9/site-packages/flask/app.py", line 1509, in dispatch_request
    return self.ensure_sync(self.view_functions[rule.endpoint])(**req.view_args)
  File "/home/desenvolvimento/Documentos/projetos/flask/microblog/venv/lib/python3.9/site-packages/flask_login/utils.py", line 272, in decorated_view
    return func(*args, **kwargs)
  File "/home/desenvolvimento/Documentos/projetos/flask/microblog/app/routes.py", line 98, in edit_profile
    db.session.commit()
  File "<string>", line 2, in commit
  File "/home/desenvolvimento/Documentos/projetos/flask/microblog/venv/lib/python3.9/site-packages/sqlalchemy/orm/session.py", line 1431, in commit
    self._transaction.commit(_to_root=self.future)
  File "/home/desenvolvimento/Documentos/projetos/flask/microblog/venv/lib/python3.9/site-packages/sqlalchemy/orm/session.py", line 829, in commit
    self._prepare_impl()
  File "/home/desenvolvimento/Documentos/projetos/flask/microblog/venv/lib/python3.9/site-packages/sqlalchemy/orm/session.py", line 808, in _prepare_impl
    self.session.flush()
  File "/home/desenvolvimento/Documentos/projetos/flask/microblog/venv/lib/python3.9/site-packages/sqlalchemy/orm/session.py", line 3363, in flush
    self._flush(objects)
  File "/home/desenvolvimento/Documentos/projetos/flask/microblog/venv/lib/python3.9/site-packages/sqlalchemy/orm/session.py", line 3503, in _flush
    transaction.rollback(_capture_exception=True)
  File "/home/desenvolvimento/Documentos/projetos/flask/microblog/venv/lib/python3.9/site-packages/sqlalchemy/util/langhelpers.py", line 70, in __exit__
    compat.raise_(
  File "/home/desenvolvimento/Documentos/projetos/flask/microblog/venv/lib/python3.9/site-packages/sqlalchemy/util/compat.py", line 207, in raise_
    raise exception
  File "/home/desenvolvimento/Documentos/projetos/flask/microblog/venv/lib/python3.9/site-packages/sqlalchemy/orm/session.py", line 3463, in _flush
    flush_context.execute()
  File "/home/desenvolvimento/Documentos/projetos/flask/microblog/venv/lib/python3.9/site-packages/sqlalchemy/orm/unitofwork.py", line 456, in execute
    rec.execute(self)
  File "/home/desenvolvimento/Documentos/projetos/flask/microblog/venv/lib/python3.9/site-packages/sqlalchemy/orm/unitofwork.py", line 630, in execute
    util.preloaded.orm_persistence.save_obj(
  File "/home/desenvolvimento/Documentos/projetos/flask/microblog/venv/lib/python3.9/site-packages/sqlalchemy/orm/persistence.py", line 236, in save_obj
    _emit_update_statements(
  File "/home/desenvolvimento/Documentos/projetos/flask/microblog/venv/lib/python3.9/site-packages/sqlalchemy/orm/persistence.py", line 1000, in _emit_update_statements
    c = connection._execute_20(
  File "/home/desenvolvimento/Documentos/projetos/flask/microblog/venv/lib/python3.9/site-packages/sqlalchemy/engine/base.py", line 1620, in _execute_20
    return meth(self, args_10style, kwargs_10style, execution_options)
  File "/home/desenvolvimento/Documentos/projetos/flask/microblog/venv/lib/python3.9/site-packages/sqlalchemy/sql/elements.py", line 325, in _execute_on_connection
    return connection._execute_clauseelement(
  File "/home/desenvolvimento/Documentos/projetos/flask/microblog/venv/lib/python3.9/site-packages/sqlalchemy/engine/base.py", line 1487, in _execute_clauseelement
    ret = self._execute_context(
  File "/home/desenvolvimento/Documentos/projetos/flask/microblog/venv/lib/python3.9/site-packages/sqlalchemy/engine/base.py", line 1851, in _execute_context
    self._handle_dbapi_exception(
  File "/home/desenvolvimento/Documentos/projetos/flask/microblog/venv/lib/python3.9/site-packages/sqlalchemy/engine/base.py", line 2032, in _handle_dbapi_exception
    util.raise_(
  File "/home/desenvolvimento/Documentos/projetos/flask/microblog/venv/lib/python3.9/site-packages/sqlalchemy/util/compat.py", line 207, in raise_
    raise exception
  File "/home/desenvolvimento/Documentos/projetos/flask/microblog/venv/lib/python3.9/site-packages/sqlalchemy/engine/base.py", line 1808, in _execute_context
    self.dialect.do_execute(
  File "/home/desenvolvimento/Documentos/projetos/flask/microblog/venv/lib/python3.9/site-packages/sqlalchemy/engine/default.py", line 732, in do_execute
    cursor.execute(statement, parameters)
sqlalchemy.exc.IntegrityError: (sqlite3.IntegrityError) UNIQUE constraint failed: user.username
[SQL: UPDATE user SET username=?, about_me=? WHERE user.id = ?]
[parameters: ('JansenDF', 'Testesss', 3)]
(Background on this error at: https://sqlalche.me/e/14/gkpj)
2022-03-30 16:46:24,929 INFO: Microblog startup [in /home/desenvolvimento/Documentos/projetos/flask/microblog/app/__init__.py:46]
