2022-04-05 18:13:38,115 ERROR: Exception on /user/Jansen [GET] [in /home/desenvolvimento/Documentos/projetos/flask/microblog/venv/lib/python3.9/site-packages/flask/app.py:1455]
Traceback (most recent call last):
  File "/home/desenvolvimento/Documentos/projetos/flask/microblog/venv/lib/python3.9/site-packages/flask/app.py", line 2077, in wsgi_app
    response = self.full_dispatch_request()
  File "/home/desenvolvimento/Documentos/projetos/flask/microblog/venv/lib/python3.9/site-packages/flask/app.py", line 1525, in full_dispatch_request
    rv = self.handle_user_exception(e)
  File "/home/desenvolvimento/Documentos/projetos/flask/microblog/venv/lib/python3.9/site-packages/flask/app.py", line 1523, in full_dispatch_request
    rv = self.dispatch_request()
  File "/home/desenvolvimento/Documentos/projetos/flask/microblog/venv/lib/python3.9/site-packages/flask/app.py", line 1509, in dispatch_request
    return self.ensure_sync(self.view_functions[rule.endpoint])(**req.view_args)
  File "/home/desenvolvimento/Documentos/projetos/flask/microblog/venv/lib/python3.9/site-packages/flask_login/utils.py", line 272, in decorated_view
    return func(*args, **kwargs)
  File "/home/desenvolvimento/Documentos/projetos/flask/microblog/app/routes.py", line 64, in user
    posts = Post.query.get(username=username)
TypeError: get() got an unexpected keyword argument 'username'
2022-04-05 18:15:02,975 INFO: Microblog startup [in /home/desenvolvimento/Documentos/projetos/flask/microblog/app/__init__.py:46]
2022-04-05 18:15:05,838 ERROR: Exception on /user/Jansen [GET] [in /home/desenvolvimento/Documentos/projetos/flask/microblog/venv/lib/python3.9/site-packages/flask/app.py:1455]
Traceback (most recent call last):
  File "/home/desenvolvimento/Documentos/projetos/flask/microblog/venv/lib/python3.9/site-packages/flask/app.py", line 2077, in wsgi_app
    response = self.full_dispatch_request()
  File "/home/desenvolvimento/Documentos/projetos/flask/microblog/venv/lib/python3.9/site-packages/flask/app.py", line 1525, in full_dispatch_request
    rv = self.handle_user_exception(e)
  File "/home/desenvolvimento/Documentos/projetos/flask/microblog/venv/lib/python3.9/site-packages/flask/app.py", line 1523, in full_dispatch_request
    rv = self.dispatch_request()
  File "/home/desenvolvimento/Documentos/projetos/flask/microblog/venv/lib/python3.9/site-packages/flask/app.py", line 1509, in dispatch_request
    return self.ensure_sync(self.view_functions[rule.endpoint])(**req.view_args)
  File "/home/desenvolvimento/Documentos/projetos/flask/microblog/venv/lib/python3.9/site-packages/flask_login/utils.py", line 272, in decorated_view
    return func(*args, **kwargs)
  File "/home/desenvolvimento/Documentos/projetos/flask/microblog/app/routes.py", line 64, in user
    posts = current_user.post.all()
AttributeError: 'User' object has no attribute 'post'
2022-04-05 18:15:40,941 INFO: Microblog startup [in /home/desenvolvimento/Documentos/projetos/flask/microblog/app/__init__.py:46]
2022-04-05 18:15:43,691 ERROR: Exception on /user/Jansen [GET] [in /home/desenvolvimento/Documentos/projetos/flask/microblog/venv/lib/python3.9/site-packages/flask/app.py:1455]
Traceback (most recent call last):
  File "/home/desenvolvimento/Documentos/projetos/flask/microblog/venv/lib/python3.9/site-packages/flask/app.py", line 2077, in wsgi_app
    response = self.full_dispatch_request()
  File "/home/desenvolvimento/Documentos/projetos/flask/microblog/venv/lib/python3.9/site-packages/flask/app.py", line 1525, in full_dispatch_request
    rv = self.handle_user_exception(e)
  File "/home/desenvolvimento/Documentos/projetos/flask/microblog/venv/lib/python3.9/site-packages/flask/app.py", line 1523, in full_dispatch_request
    rv = self.dispatch_request()
  File "/home/desenvolvimento/Documentos/projetos/flask/microblog/venv/lib/python3.9/site-packages/flask/app.py", line 1509, in dispatch_request
    return self.ensure_sync(self.view_functions[rule.endpoint])(**req.view_args)
  File "/home/desenvolvimento/Documentos/projetos/flask/microblog/venv/lib/python3.9/site-packages/flask_login/utils.py", line 272, in decorated_view
    return func(*args, **kwargs)
  File "/home/desenvolvimento/Documentos/projetos/flask/microblog/app/routes.py", line 64, in user
    posts = current_user.post.all()
AttributeError: 'User' object has no attribute 'post'
2022-04-05 18:17:22,874 INFO: Microblog startup [in /home/desenvolvimento/Documentos/projetos/flask/microblog/app/__init__.py:46]
2022-04-05 18:17:25,271 ERROR: Exception on /user/Jansen [GET] [in /home/desenvolvimento/Documentos/projetos/flask/microblog/venv/lib/python3.9/site-packages/flask/app.py:1455]
Traceback (most recent call last):
  File "/home/desenvolvimento/Documentos/projetos/flask/microblog/venv/lib/python3.9/site-packages/flask/app.py", line 2077, in wsgi_app
    response = self.full_dispatch_request()
  File "/home/desenvolvimento/Documentos/projetos/flask/microblog/venv/lib/python3.9/site-packages/flask/app.py", line 1525, in full_dispatch_request
    rv = self.handle_user_exception(e)
  File "/home/desenvolvimento/Documentos/projetos/flask/microblog/venv/lib/python3.9/site-packages/flask/app.py", line 1523, in full_dispatch_request
    rv = self.dispatch_request()
  File "/home/desenvolvimento/Documentos/projetos/flask/microblog/venv/lib/python3.9/site-packages/flask/app.py", line 1509, in dispatch_request
    return self.ensure_sync(self.view_functions[rule.endpoint])(**req.view_args)
  File "/home/desenvolvimento/Documentos/projetos/flask/microblog/venv/lib/python3.9/site-packages/flask_login/utils.py", line 272, in decorated_view
    return func(*args, **kwargs)
  File "/home/desenvolvimento/Documentos/projetos/flask/microblog/app/routes.py", line 64, in user
    posts = current_user.Post()
AttributeError: 'User' object has no attribute 'Post'
2022-04-05 18:19:25,480 INFO: Microblog startup [in /home/desenvolvimento/Documentos/projetos/flask/microblog/app/__init__.py:46]
2022-04-05 18:20:19,180 INFO: Microblog startup [in /home/desenvolvimento/Documentos/projetos/flask/microblog/app/__init__.py:46]
2022-04-05 18:20:21,615 ERROR: Exception on /user/Jansen [GET] [in /home/desenvolvimento/Documentos/projetos/flask/microblog/venv/lib/python3.9/site-packages/flask/app.py:1455]
Traceback (most recent call last):
  File "/home/desenvolvimento/Documentos/projetos/flask/microblog/venv/lib/python3.9/site-packages/flask/app.py", line 2077, in wsgi_app
    response = self.full_dispatch_request()
  File "/home/desenvolvimento/Documentos/projetos/flask/microblog/venv/lib/python3.9/site-packages/flask/app.py", line 1525, in full_dispatch_request
    rv = self.handle_user_exception(e)
  File "/home/desenvolvimento/Documentos/projetos/flask/microblog/venv/lib/python3.9/site-packages/flask/app.py", line 1523, in full_dispatch_request
    rv = self.dispatch_request()
  File "/home/desenvolvimento/Documentos/projetos/flask/microblog/venv/lib/python3.9/site-packages/flask/app.py", line 1509, in dispatch_request
    return self.ensure_sync(self.view_functions[rule.endpoint])(**req.view_args)
  File "/home/desenvolvimento/Documentos/projetos/flask/microblog/venv/lib/python3.9/site-packages/flask_login/utils.py", line 272, in decorated_view
    return func(*args, **kwargs)
  File "/home/desenvolvimento/Documentos/projetos/flask/microblog/app/routes.py", line 66, in user
    return render_template('user.html', title='Profile', user=user, posts=posts, form=form)
  File "/home/desenvolvimento/Documentos/projetos/flask/microblog/venv/lib/python3.9/site-packages/flask/templating.py", line 148, in render_template
    return _render(
  File "/home/desenvolvimento/Documentos/projetos/flask/microblog/venv/lib/python3.9/site-packages/flask/templating.py", line 128, in _render
    rv = template.render(context)
  File "/home/desenvolvimento/Documentos/projetos/flask/microblog/venv/lib/python3.9/site-packages/jinja2/environment.py", line 1291, in render
    self.environment.handle_exception()
  File "/home/desenvolvimento/Documentos/projetos/flask/microblog/venv/lib/python3.9/site-packages/jinja2/environment.py", line 926, in handle_exception
    raise rewrite_traceback_stack(source=source)
  File "/home/desenvolvimento/Documentos/projetos/flask/microblog/app/templates/user.html", line 1, in top-level template code
    {% extends "base.html" %}
  File "/home/desenvolvimento/Documentos/projetos/flask/microblog/app/templates/base.html", line 33, in top-level template code
    {% block content %}
  File "/home/desenvolvimento/Documentos/projetos/flask/microblog/app/templates/user.html", line 37, in block 'content'
    {% for post in posts %}
TypeError: 'NoneType' object is not iterable
2022-04-05 18:20:33,996 INFO: Microblog startup [in /home/desenvolvimento/Documentos/projetos/flask/microblog/app/__init__.py:46]
