2022-04-05 15:33:08,928 ERROR: Exception on /user/JansenDF [GET] [in /home/desenvolvimento/Documentos/projetos/flask/microblog/venv/lib/python3.9/site-packages/flask/app.py:1455]
Traceback (most recent call last):
  File "/home/desenvolvimento/Documentos/projetos/flask/microblog/venv/lib/python3.9/site-packages/flask/app.py", line 2077, in wsgi_app
    response = self.full_dispatch_request()
  File "/home/desenvolvimento/Documentos/projetos/flask/microblog/venv/lib/python3.9/site-packages/flask/app.py", line 1525, in full_dispatch_request
    rv = self.handle_user_exception(e)
  File "/home/desenvolvimento/Documentos/projetos/flask/microblog/venv/lib/python3.9/site-packages/flask/app.py", line 1523, in full_dispatch_request
    rv = self.dispatch_request()
  File "/home/desenvolvimento/Documentos/projetos/flask/microblog/venv/lib/python3.9/site-packages/flask/app.py", line 1509, in dispatch_request
    return self.ensure_sync(self.view_functions[rule.endpoint])(**req.view_args)
  File "/home/desenvolvimento/Documentos/projetos/flask/microblog/venv/lib/python3.9/site-packages/flask_login/utils.py", line 272, in decorated_view
    return func(*args, **kwargs)
  File "/home/desenvolvimento/Documentos/projetos/flask/microblog/app/routes.py", line 84, in user
    return render_template('user.html', title='Profile', user=user, posts=posts, form=form)
  File "/home/desenvolvimento/Documentos/projetos/flask/microblog/venv/lib/python3.9/site-packages/flask/templating.py", line 149, in render_template
    ctx.app.jinja_env.get_or_select_template(template_name_or_list),
  File "/home/desenvolvimento/Documentos/projetos/flask/microblog/venv/lib/python3.9/site-packages/jinja2/environment.py", line 1071, in get_or_select_template
    return self.get_template(template_name_or_list, parent, globals)
  File "/home/desenvolvimento/Documentos/projetos/flask/microblog/venv/lib/python3.9/site-packages/jinja2/environment.py", line 1000, in get_template
    return self._load_template(name, globals)
  File "/home/desenvolvimento/Documentos/projetos/flask/microblog/venv/lib/python3.9/site-packages/jinja2/environment.py", line 959, in _load_template
    template = self.loader.load(self, name, self.make_globals(globals))
  File "/home/desenvolvimento/Documentos/projetos/flask/microblog/venv/lib/python3.9/site-packages/jinja2/loaders.py", line 138, in load
    code = environment.compile(source, name, filename)
  File "/home/desenvolvimento/Documentos/projetos/flask/microblog/venv/lib/python3.9/site-packages/jinja2/environment.py", line 758, in compile
    self.handle_exception(source=source_hint)
  File "/home/desenvolvimento/Documentos/projetos/flask/microblog/venv/lib/python3.9/site-packages/jinja2/environment.py", line 926, in handle_exception
    raise rewrite_traceback_stack(source=source)
  File "/home/desenvolvimento/Documentos/projetos/flask/microblog/app/templates/user.html", line 15, in template
    <p>{{ user.followers.count() }} followers, {{ user.followed.count() }, following.}</p>
jinja2.exceptions.TemplateSyntaxError: unexpected '}'
2022-04-05 15:33:45,018 INFO: Microblog startup [in /home/desenvolvimento/Documentos/projetos/flask/microblog/app/__init__.py:46]
2022-04-05 15:34:20,462 INFO: Microblog startup [in /home/desenvolvimento/Documentos/projetos/flask/microblog/app/__init__.py:46]
2022-04-05 15:45:42,248 INFO: Microblog startup [in /home/desenvolvimento/Documentos/projetos/flask/microblog/app/__init__.py:46]
2022-04-05 15:47:00,742 INFO: Microblog startup [in /home/desenvolvimento/Documentos/projetos/flask/microblog/app/__init__.py:46]
2022-04-05 15:50:02,582 INFO: Microblog startup [in /home/desenvolvimento/Documentos/projetos/flask/microblog/app/__init__.py:46]
2022-04-05 17:29:03,633 INFO: Microblog startup [in /home/desenvolvimento/Documentos/projetos/flask/microblog/app/__init__.py:46]
2022-04-05 17:29:08,254 ERROR: Exception on /index [GET] [in /home/desenvolvimento/Documentos/projetos/flask/microblog/venv/lib/python3.9/site-packages/flask/app.py:1455]
Traceback (most recent call last):
  File "/home/desenvolvimento/Documentos/projetos/flask/microblog/venv/lib/python3.9/site-packages/flask/app.py", line 2077, in wsgi_app
    response = self.full_dispatch_request()
  File "/home/desenvolvimento/Documentos/projetos/flask/microblog/venv/lib/python3.9/site-packages/flask/app.py", line 1525, in full_dispatch_request
    rv = self.handle_user_exception(e)
  File "/home/desenvolvimento/Documentos/projetos/flask/microblog/venv/lib/python3.9/site-packages/flask/app.py", line 1523, in full_dispatch_request
    rv = self.dispatch_request()
  File "/home/desenvolvimento/Documentos/projetos/flask/microblog/venv/lib/python3.9/site-packages/flask/app.py", line 1509, in dispatch_request
    return self.ensure_sync(self.view_functions[rule.endpoint])(**req.view_args)
  File "/home/desenvolvimento/Documentos/projetos/flask/microblog/venv/lib/python3.9/site-packages/flask_login/utils.py", line 272, in decorated_view
    return func(*args, **kwargs)
  File "/home/desenvolvimento/Documentos/projetos/flask/microblog/app/routes.py", line 21, in index
    posts = current_user.followed+posts().all()
UnboundLocalError: local variable 'posts' referenced before assignment
2022-04-05 17:29:27,651 ERROR: Exception on /index [GET] [in /home/desenvolvimento/Documentos/projetos/flask/microblog/venv/lib/python3.9/site-packages/flask/app.py:1455]
Traceback (most recent call last):
  File "/home/desenvolvimento/Documentos/projetos/flask/microblog/venv/lib/python3.9/site-packages/flask/app.py", line 2077, in wsgi_app
    response = self.full_dispatch_request()
  File "/home/desenvolvimento/Documentos/projetos/flask/microblog/venv/lib/python3.9/site-packages/flask/app.py", line 1525, in full_dispatch_request
    rv = self.handle_user_exception(e)
  File "/home/desenvolvimento/Documentos/projetos/flask/microblog/venv/lib/python3.9/site-packages/flask/app.py", line 1523, in full_dispatch_request
    rv = self.dispatch_request()
  File "/home/desenvolvimento/Documentos/projetos/flask/microblog/venv/lib/python3.9/site-packages/flask/app.py", line 1509, in dispatch_request
    return self.ensure_sync(self.view_functions[rule.endpoint])(**req.view_args)
  File "/home/desenvolvimento/Documentos/projetos/flask/microblog/venv/lib/python3.9/site-packages/flask_login/utils.py", line 272, in decorated_view
    return func(*args, **kwargs)
  File "/home/desenvolvimento/Documentos/projetos/flask/microblog/app/routes.py", line 21, in index
    posts = current_user.followed+posts().all()
UnboundLocalError: local variable 'posts' referenced before assignment
2022-04-05 17:32:13,528 INFO: Microblog startup [in /home/desenvolvimento/Documentos/projetos/flask/microblog/app/__init__.py:46]
2022-04-05 17:43:16,244 INFO: Microblog startup [in /home/desenvolvimento/Documentos/projetos/flask/microblog/app/__init__.py:46]
2022-04-05 17:43:26,293 ERROR: Exception on /index [GET] [in /home/desenvolvimento/Documentos/projetos/flask/microblog/venv/lib/python3.9/site-packages/flask/app.py:1455]
Traceback (most recent call last):
  File "/home/desenvolvimento/Documentos/projetos/flask/microblog/venv/lib/python3.9/site-packages/flask/app.py", line 2077, in wsgi_app
    response = self.full_dispatch_request()
  File "/home/desenvolvimento/Documentos/projetos/flask/microblog/venv/lib/python3.9/site-packages/flask/app.py", line 1525, in full_dispatch_request
    rv = self.handle_user_exception(e)
  File "/home/desenvolvimento/Documentos/projetos/flask/microblog/venv/lib/python3.9/site-packages/flask/app.py", line 1523, in full_dispatch_request
    rv = self.dispatch_request()
  File "/home/desenvolvimento/Documentos/projetos/flask/microblog/venv/lib/python3.9/site-packages/flask/app.py", line 1509, in dispatch_request
    return self.ensure_sync(self.view_functions[rule.endpoint])(**req.view_args)
  File "/home/desenvolvimento/Documentos/projetos/flask/microblog/venv/lib/python3.9/site-packages/flask_login/utils.py", line 272, in decorated_view
    return func(*args, **kwargs)
  File "/home/desenvolvimento/Documentos/projetos/flask/microblog/app/routes.py", line 22, in index
    return render_template('index.html', title='Home', form=form, posts=posts)
  File "/home/desenvolvimento/Documentos/projetos/flask/microblog/venv/lib/python3.9/site-packages/flask/templating.py", line 149, in render_template
    ctx.app.jinja_env.get_or_select_template(template_name_or_list),
  File "/home/desenvolvimento/Documentos/projetos/flask/microblog/venv/lib/python3.9/site-packages/jinja2/environment.py", line 1071, in get_or_select_template
    return self.get_template(template_name_or_list, parent, globals)
  File "/home/desenvolvimento/Documentos/projetos/flask/microblog/venv/lib/python3.9/site-packages/jinja2/environment.py", line 1000, in get_template
    return self._load_template(name, globals)
  File "/home/desenvolvimento/Documentos/projetos/flask/microblog/venv/lib/python3.9/site-packages/jinja2/environment.py", line 959, in _load_template
    template = self.loader.load(self, name, self.make_globals(globals))
  File "/home/desenvolvimento/Documentos/projetos/flask/microblog/venv/lib/python3.9/site-packages/jinja2/loaders.py", line 138, in load
    code = environment.compile(source, name, filename)
  File "/home/desenvolvimento/Documentos/projetos/flask/microblog/venv/lib/python3.9/site-packages/jinja2/environment.py", line 758, in compile
    self.handle_exception(source=source_hint)
  File "/home/desenvolvimento/Documentos/projetos/flask/microblog/venv/lib/python3.9/site-packages/jinja2/environment.py", line 926, in handle_exception
    raise rewrite_traceback_stack(source=source)
  File "/home/desenvolvimento/Documentos/projetos/flask/microblog/app/templates/index.html", line 19, in template
    {% endfor %}
jinja2.exceptions.TemplateSyntaxError: Encountered unknown tag 'endfor'. Jinja was looking for the following tags: 'elif' or 'else' or 'endif'. The innermost block that needs to be closed is 'if'.
